Workbook

Sheet Weekly-raw
A1: SPX Index Weekly | C1: LBUSTRUU Index Weekly | E1: LD12TRUU Index weekly | G1: VIX Index weekly | I1: USGG3M Index Weekly | K1: SPTR Index weekly
A2: Date | B2: Last Price | C2: Date | D2: Last Price | E2: Date | F2: Last Price | G2: Date | H2: Last Price | I2: Date | J2: Last Price | K2: Date | L2: Last Price
A3: 46288 | B3: 7702.78 | C3: 46287 | D3: 2321.55 | E3: 46287 | F3: 244.82 | G3: 46288 | H3: 15.35 | I3: 46288 | J3: 4.1226 | K3: 46287 | L3: 17411.799
A4: 46283 | B4: 7650.5 | C4: 46283 | D4: 2314.44 | E4: 46283 | F4: 244.77 | G4: 46283 | H4: 14.81 | I4: 46283 | J4: 4.0703 | K4: 46283 | L4: 17154.355
A5: 46276 | B5: 7656.98 | C5: 46276 | D5: 2315.23 | E5: 46276 | F5: 244.59 | G5: 46276 | H5: 15.84 | I5: 46276 | J5: 4.0002 | K5: 46276 | L5: 17164.105
A6: 46269 | B6: 7718.6 | C6: 46269 | D6: 2339.55 | E6: 46269 | F6: 244.48 | G6: 46269 | H6: 14.53 | I6: 46269 | J6: 3.8445 | K6: 46269 | L6: 17298.34
A7: 46262 | B7: 7711.76 | C7: 46262 | D7: 2343.86 | E7: 46262 | F7: 244.27 | G7: 46262 | H7: 14.43 | I7: 46262 | J7: 3.8043 | K7: 46262 | L7: 17276.494
A8: 46255 | B8: 7674.37 | C8: 46255 | D8: 2340.79 | E8: 46255 | F8: 244.11 | G8: 46255 | H8: 15.13 | I8: 46255 | J8: 3.7936 | K8: 46255 | L8: 17190.768
A9: 46248 | B9: 7785.76 | C9: 46248 | D9: 2343.23 | E9: 46248 | F9: 243.93 | G9: 46248 | H9: 14.25 | I9: 46248 | J9: 3.78 | K9: 46248 | L9: 17433.301
A10: 46241 | B10: 7757.64 | C10: 46241 | D10: 2346.62 | E10: 46241 | F10: 243.76 | G10: 46241 | H10: 14.9 | I10: 46241 | J10: 3.7948 | K10: 46241 | L10: 17365.137
A11: 46234 | B11: 7489.72 | C11: 46234 | D11: 2332.59 | E11: 46234 | F11: 243.58 | G11: 46234 | H11: 15.99 | I11: 46234 | J11: 3.7529 | K11: 46234 | L11: 16763.426
A12: 46227 | B12: 7411.98 | C12: 46227 | D12: 2335.4 | E12: 46227 | F12: 243.4 | G12: 46227 | H12: 18.58 | I12: 46227 | J12: 3.8978 | K12: 46227 | L12: 16588.01
A13: 46220 | B13: 7457.69 | C13: 46220 | D13: 2352.71 | E13: 46220 | F13: 243.24 | G13: 46220 | H13: 18.77 | I13: 46220 | J13: 3.7926 | K13: 46220 | L13: 16687.557
A14: 46213 | B14: 7575.39 | C14: 46213 | D14: 2349.73 | E14: 46213 | F14: 243.07 | G14: 46213 | H14: 15.03 | I14: 46213 | J14: 3.7798 | K14: 46213 | L14: 16949.551
... A1397: 36532 | B1397: 1441.47 | C1397: 36532 | D1397: 833.27 | E1397: 36532 | F1397: 144.81 | G1397: 36532 | H1397: 21.72 | I1397: 36532 | J1397: 5.38 | K1397: 36532 | L1397: 1983.832

Sheet Weekly
A1: date | B1: spx | C1: bond_index | D1: money_market | E1: vix | F1: short_term_yield | G1: sptr
A2: 46288 | B2: =_xlfn.XLOOKUP(A:A,'Weekly-raw'!A:A,'Weekly-raw'!B:B) -> 7702.78 | C2: =_xlfn.XLOOKUP(A:A,'Weekly-raw'!C:C,'Weekly-raw'!D:D) -> #N/A | D2: =_xlfn.XLOOKUP(A:A,'Weekly-raw'!E:E,'Weekly-raw'!F:F) -> #N/A | E2: =_xlfn.XLOOKUP(A:A,'Weekly-raw'!G:G,'Weekly-raw'!H:H) -> 15.35 | F2: =_xlfn.XLOOKUP(A:A,'Weekly-raw'!I:I,'Weekly-raw'!J:J) -> 4.1226 | G2: =_xlfn.XLOOKUP(A:A,'Weekly-raw'!K:K,'Weekly-raw'!L:L) -> #N/A
A3: 46283 | B3: =_xlfn.XLOOKUP(A:A,'Weekly-raw'!A:A,'Weekly-raw'!B:B) -> 7650.5 | C3: =_xlfn.XLOOKUP(A:A,'Weekly-raw'!C:C,'Weekly-raw'!D:D) -> 2314.44 | D3: =_xlfn.XLOOKUP(A:A,'Weekly-raw'!E:E,'Weekly-raw'!F:F) -> 244.77 | E3: =_xlfn.XLOOKUP(A:A,'Weekly-raw'!G:G,'Weekly-raw'!H:H) -> 14.81 | F3: =_xlfn.XLOOKUP(A:A,'Weekly-raw'!I:I,'Weekly-raw'!J:J) -> 4.0703 | G3: =_xlfn.XLOOKUP(A:A,'Weekly-raw'!K:K,'Weekly-raw'!L:L) -> 17154.355
A4: 46276 | B4: =_xlfn.XLOOKUP(A:A,'Weekly-raw'!A:A,'Weekly-raw'!B:B) -> 7656.98 | C4: =_xlfn.XLOOKUP(A:A,'Weekly-raw'!C:C,'Weekly-raw'!D:D) -> 2315.23 | D4: =_xlfn.XLOOKUP(A:A,'Weekly-raw'!E:E,'Weekly-raw'!F:F) -> 244.59 | E4: =_xlfn.XLOOKUP(A:A,'Weekly-raw'!G:G,'Weekly-raw'!H:H) -> 15.84 | F4: =_xlfn.XLOOKUP(A:A,'Weekly-raw'!I:I,'Weekly-raw'!J:J) -> 4.0002 | G4: =_xlfn.XLOOKUP(A:A,'Weekly-raw'!K:K,'Weekly-raw'!L:L) -> 17164.105
A5: 46269 | B5: =_xlfn.XLOOKUP(A:A,'Weekly-raw'!A:A,'Weekly-raw'!B:B) -> 7718.6 | C5: =_xlfn.XLOOKUP(A:A,'Weekly-raw'!C:C,'Weekly-raw'!D:D) -> 2339.55 | D5: =_xlfn.XLOOKUP(A:A,'Weekly-raw'!E:E,'Weekly-raw'!F:F) -> 244.48 | E5: =_xlfn.XLOOKUP(A:A,'Weekly-raw'!G:G,'Weekly-raw'!H:H) -> 14.53 | F5: =_xlfn.XLOOKUP(A:A,'Weekly-raw'!I:I,'Weekly-raw'!J:J) -> 3.8445 | G5: =_xlfn.XLOOKUP(A:A,'Weekly-raw'!K:K,'Weekly-raw'!L:L) -> 17298.34
A6: 46262 | B6: =_xlfn.XLOOKUP(A:A,'Weekly-raw'!A:A,'Weekly-raw'!B:B) -> 7711.76 | C6: =_xlfn.XLOOKUP(A:A,'Weekly-raw'!C:C,'Weekly-raw'!D:D) -> 2343.86 | D6: =_xlfn.XLOOKUP(A:A,'Weekly-raw'!E:E,'Weekly-raw'!F:F) -> 244.27 | E6: =_xlfn.XLOOKUP(A:A,'Weekly-raw'!G:G,'Weekly-raw'!H:H) -> 14.43 | F6: =_xlfn.XLOOKUP(A:A,'Weekly-raw'!I:I,'Weekly-raw'!J:J) -> 3.8043 | G6: =_xlfn.XLOOKUP(A:A,'Weekly-raw'!K:K,'Weekly-raw'!L:L) -> 17276.494
A7: 46255 | B7: =_xlfn.XLOOKUP(A:A,'Weekly-raw'!A:A,'Weekly-raw'!B:B) -> 7674.37 | C7: =_xlfn.XLOOKUP(A:A,'Weekly-raw'!C:C,'Weekly-raw'!D:D) -> 2340.79 | D7: =_xlfn.XLOOKUP(A:A,'Weekly-raw'!E:E,'Weekly-raw'!F:F) -> 244.11 | E7: =_xlfn.XLOOKUP(A:A,'Weekly-raw'!G:G,'Weekly-raw'!H:H) -> 15.13 | F7: =_xlfn.XLOOKUP(A:A,'Weekly-raw'!I:I,'Weekly-raw'!J:J) -> 3.7936 | G7: =_xlfn.XLOOKUP(A:A,'Weekly-raw'!K:K,'Weekly-raw'!L:L) -> 17190.768
A8: 46248 | B8: =_xlfn.XLOOKUP(A:A,'Weekly-raw'!A:A,'Weekly-raw'!B:B) -> 7785.76 | C8: =_xlfn.XLOOKUP(A:A,'Weekly-raw'!C:C,'Weekly-raw'!D:D) -> 2343.23 | D8: =_xlfn.XLOOKUP(A:A,'Weekly-raw'!E:E,'Weekly-raw'!F:F) -> 243.93 | E8: =_xlfn.XLOOKUP(A:A,'Weekly-raw'!G:G,'Weekly-raw'!H:H) -> 14.25 | F8: =_xlfn.XLOOKUP(A:A,'Weekly-raw'!I:I,'Weekly-raw'!J:J) -> 3.78 | G8: =_xlfn.XLOOKUP(A:A,'Weekly-raw'!K:K,'Weekly-raw'!L:L) -> 17433.301
A9: 46241 | B9: =_xlfn.XLOOKUP(A:A,'Weekly-raw'!A:A,'Weekly-raw'!B:B) -> 7757.64 | C9: =_xlfn.XLOOKUP(A:A,'Weekly-raw'!C:C,'Weekly-raw'!D:D) -> 2346.62 | D9: =_xlfn.XLOOKUP(A:A,'Weekly-raw'!E:E,'Weekly-raw'!F:F) -> 243.76 | E9: =_xlfn.XLOOKUP(A:A,'Weekly-raw'!G:G,'Weekly-raw'!H:H) -> 14.9 | F9: =_xlfn.XLOOKUP(A:A,'Weekly-raw'!I:I,'Weekly-raw'!J:J) -> 3.7948 | G9: =_xlfn.XLOOKUP(A:A,'Weekly-raw'!K:K,'Weekly-raw'!L:L) -> 17365.137
A10: 46234 | B10: =_xlfn.XLOOKUP(A:A,'Weekly-raw'!A:A,'Weekly-raw'!B:B) -> 7489.72 | C10: =_xlfn.XLOOKUP(A:A,'Weekly-raw'!C:C,'Weekly-raw'!D:D) -> 2332.59 | D10: =_xlfn.XLOOKUP(A:A,'Weekly-raw'!E:E,'Weekly-raw'!F:F) -> 243.58 | E10: =_xlfn.XLOOKUP(A:A,'Weekly-raw'!G:G,'Weekly-raw'!H:H) -> 15.99 | F10: =_xlfn.XLOOKUP(A:A,'Weekly-raw'!I:I,'Weekly-raw'!J:J) -> 3.7529 | G10: =_xlfn.XLOOKUP(A:A,'Weekly-raw'!K:K,'Weekly-raw'!L:L) -> 16763.426
A11: 46227 | B11: =_xlfn.XLOOKUP(A:A,'Weekly-raw'!A:A,'Weekly-raw'!B:B) -> 7411.98 | C11: =_xlfn.XLOOKUP(A:A,'Weekly-raw'!C:C,'Weekly-raw'!D:D) -> 2335.4 | D11: =_xlfn.XLOOKUP(A:A,'Weekly-raw'!E:E,'Weekly-raw'!F:F) -> 243.4 | E11: =_xlfn.XLOOKUP(A:A,'Weekly-raw'!G:G,'Weekly-raw'!H:H) -> 18.58 | F11: =_xlfn.XLOOKUP(A:A,'Weekly-raw'!I:I,'Weekly-raw'!J:J) -> 3.8978 | G11: =_xlfn.XLOOKUP(A:A,'Weekly-raw'!K:K,'Weekly-raw'!L:L) -> 16588.01
A12: 46220 | B12: =_xlfn.XLOOKUP(A:A,'Weekly-raw'!A:A,'Weekly-raw'!B:B) -> 7457.69 | C12: =_xlfn.XLOOKUP(A:A,'Weekly-raw'!C:C,'Weekly-raw'!D:D) -> 2352.71 | D12: =_xlfn.XLOOKUP(A:A,'Weekly-raw'!E:E,'Weekly-raw'!F:F) -> 243.24 | E12: =_xlfn.XLOOKUP(A:A,'Weekly-raw'!G:G,'Weekly-raw'!H:H) -> 18.77 | F12: =_xlfn.XLOOKUP(A:A,'Weekly-raw'!I:I,'Weekly-raw'!J:J) -> 3.7926 | G12: =_xlfn.XLOOKUP(A:A,'Weekly-raw'!K:K,'Weekly-raw'!L:L) -> 16687.557
A13: 46213 | B13: =_xlfn.XLOOKUP(A:A,'Weekly-raw'!A:A,'Weekly-raw'!B:B) -> 7575.39 | C13: =_xlfn.XLOOKUP(A:A,'Weekly-raw'!C:C,'Weekly-raw'!D:D) -> 2349.73 | D13: =_xlfn.XLOOKUP(A:A,'Weekly-raw'!E:E,'Weekly-raw'!F:F) -> 243.07 | E13: =_xlfn.XLOOKUP(A:A,'Weekly-raw'!G:G,'Weekly-raw'!H:H) -> 15.03 | F13: =_xlfn.XLOOKUP(A:A,'Weekly-raw'!I:I,'Weekly-raw'!J:J) -> 3.7798 | G13: =_xlfn.XLOOKUP(A:A,'Weekly-raw'!K:K,'Weekly-raw'!L:L) -> 16949.551
... A1396: 36532 | B1396: =_xlfn.XLOOKUP(A:A,'Weekly-raw'!A:A,'Weekly-raw'!B:B) -> 1441.47 | C1396: =_xlfn.XLOOKUP(A:A,'Weekly-raw'!C:C,'Weekly-raw'!D:D) -> 833.27 | D1396: =_xlfn.XLOOKUP(A:A,'Weekly-raw'!E:E,'Weekly-raw'!F:F) -> 144.81 | E1396: =_xlfn.XLOOKUP(A:A,'Weekly-raw'!G:G,'Weekly-raw'!H:H) -> 21.72 | F1396: =_xlfn.XLOOKUP(A:A,'Weekly-raw'!I:I,'Weekly-raw'!J:J) -> 5.38 | G1396: =_xlfn.XLOOKUP(A:A,'Weekly-raw'!K:K,'Weekly-raw'!L:L) -> 1983.832

Sheet Monthly-raw
A1: SPX Index | C1: LBUSTRUU Index | E1: LD12TRUU Index | G1: VIX Index | I1: USGG3M Index | K1: SPTR Index
A2: Date | B2: Last Price | C2: Date | D2: Last Price | E2: Date | F2: Last Price | G2: Date | H2: Last Price | I2: Date | J2: Last Price | K2: Date | L2: Last Price
A3: 46288 | B3: 7706.55 | C3: 46287 | D3: 2321.55 | E3: 46287 | F3: 244.82 | G3: 46288 | H3: 15.26 | I3: 46288 | J3: 4.1273 | K3: 46287 | L3: 17411.799
A4: 46265 | B4: 7686.14 | C4: 46265 | D4: 2341.67 | E4: 46265 | F4: 244.3 | G4: 46265 | H4: 14.92 | I4: 46265 | J4: 3.8261 | K4: 46265 | L4: 17219.945
A5: 46234 | B5: 7489.72 | C5: 46234 | D5: 2332.59 | E5: 46234 | F5: 243.58 | G5: 46234 | H5: 15.99 | I5: 46234 | J5: 3.7529 | K5: 46234 | L5: 16763.426
A6: 46203 | B6: 7499.36 | C6: 46203 | D6: 2363.38 | E6: 46203 | F6: 242.76 | G6: 46203 | H6: 16.45 | I6: 46203 | J6: 3.8105 | K6: 46203 | L6: 16774.07
A7: 46171 | B7: 7580.06 | C7: 46171 | D7: 2357.7 | E7: 46171 | F7: 242.04 | G7: 46171 | H7: 15.32 | I7: 46171 | J7: 3.67 | K7: 46171 | L7: 16935.346
A8: 46142 | B8: 7209.01 | C8: 46142 | D8: 2350.38 | E8: 46142 | F8: 241.29 | G8: 46142 | H8: 16.89 | I8: 46142 | J8: 3.6604 | K8: 46142 | L8: 16088.562
A9: 46112 | B9: 6528.52 | C9: 46112 | D9: 2347.75 | E9: 46112 | F9: 240.56 | G9: 46112 | H9: 25.25 | I9: 46112 | J9: 3.6718 | K9: 46112 | L9: 14560.752
A10: 46080 | B10: 6878.88 | C10: 46080 | D10: 2389.86 | E10: 46080 | F10: 239.84 | G10: 46080 | H10: 19.86 | I10: 46080 | J10: 3.6562 | K10: 46080 | L10: 15323.803
A11: 46052 | B11: 6939.03 | C11: 46052 | D11: 2351.36 | E11: 46052 | F11: 239.17 | G11: 46052 | H11: 17.44 | I11: 46052 | J11: 3.6537 | K11: 46052 | L11: 15441.154
A12: 46022 | B12: 6845.5 | C12: 46022 | D12: 2348.85 | E12: 46022 | F12: 238.46 | G12: 46022 | H12: 14.95 | I12: 46022 | J12: 3.6264 | K12: 46022 | L12: 15220.455
A13: 45989 | B13: 6849.09 | C13: 45989 | D13: 2352.33 | E13: 45989 | F13: 237.63 | G13: 45989 | H13: 16.35 | I13: 45989 | J13: 3.7956 | K13: 45989 | L13: 15211.142
A14: 45961 | B14: 6840.2 | C14: 45961 | D14: 2337.8 | E14: 45961 | F14: 236.93 | G14: 45961 | H14: 17.44 | I14: 45961 | J14: 3.8007 | K14: 45961 | L14: 15173.95
... A363: 35338 | B363: 687.31 | C363: 35338 | D363: 684.83 | E363: 35338 | F363: 123.07 | G363: 35338 | H363: 16.95 | I363: 35338 | J363: 5.032 | K363: 35338 | L363: 898.966

Sheet Monthly
A1: date | B1: spx | C1: bond_index | D1: money_market | E1: vix | F1: short_term_yield | G1: sptr
A2: 46288 | B2: =_xlfn.XLOOKUP(A:A,'Monthly-raw'!A:A,'Monthly-raw'!B:B) -> 7706.55 | C2: =_xlfn.XLOOKUP(A:A,'Monthly-raw'!C:C,'Monthly-raw'!D:D) -> #N/A | D2: =_xlfn.XLOOKUP(A:A,'Monthly-raw'!E:E,'Monthly-raw'!F:F) -> #N/A | E2: =_xlfn.XLOOKUP(A:A,'Monthly-raw'!G:G,'Monthly-raw'!H:H) -> 15.26 | F2: =_xlfn.XLOOKUP(A:A,'Monthly-raw'!I:I,'Monthly-raw'!J:J) -> 4.1273 | G2: =_xlfn.XLOOKUP(A:A,'Monthly-raw'!K:K,'Monthly-raw'!L:L) -> #N/A
A3: 46265 | B3: =_xlfn.XLOOKUP(A:A,'Monthly-raw'!A:A,'Monthly-raw'!B:B) -> 7686.14 | C3: =_xlfn.XLOOKUP(A:A,'Monthly-raw'!C:C,'Monthly-raw'!D:D) -> 2341.67 | D3: =_xlfn.XLOOKUP(A:A,'Monthly-raw'!E:E,'Monthly-raw'!F:F) -> 244.3 | E3: =_xlfn.XLOOKUP(A:A,'Monthly-raw'!G:G,'Monthly-raw'!H:H) -> 14.92 | F3: =_xlfn.XLOOKUP(A:A,'Monthly-raw'!I:I,'Monthly-raw'!J:J) -> 3.8261 | G3: =_xlfn.XLOOKUP(A:A,'Monthly-raw'!K:K,'Monthly-raw'!L:L) -> 17219.945
A4: 46234 | B4: =_xlfn.XLOOKUP(A:A,'Monthly-raw'!A:A,'Monthly-raw'!B:B) -> 7489.72 | C4: =_xlfn.XLOOKUP(A:A,'Monthly-raw'!C:C,'Monthly-raw'!D:D) -> 2332.59 | D4: =_xlfn.XLOOKUP(A:A,'Monthly-raw'!E:E,'Monthly-raw'!F:F) -> 243.58 | E4: =_xlfn.XLOOKUP(A:A,'Monthly-raw'!G:G,'Monthly-raw'!H:H) -> 15.99 | F4: =_xlfn.XLOOKUP(A:A,'Monthly-raw'!I:I,'Monthly-raw'!J:J) -> 3.7529 | G4: =_xlfn.XLOOKUP(A:A,'Monthly-raw'!K:K,'Monthly-raw'!L:L) -> 16763.426
A5: 46203 | B5: =_xlfn.XLOOKUP(A:A,'Monthly-raw'!A:A,'Monthly-raw'!B:B) -> 7499.36 | C5: =_xlfn.XLOOKUP(A:A,'Monthly-raw'!C:C,'Monthly-raw'!D:D) -> 2363.38 | D5: =_xlfn.XLOOKUP(A:A,'Monthly-raw'!E:E,'Monthly-raw'!F:F) -> 242.76 | E5: =_xlfn.XLOOKUP(A:A,'Monthly-raw'!G:G,'Monthly-raw'!H:H) -> 16.45 | F5: =_xlfn.XLOOKUP(A:A,'Monthly-raw'!I:I,'Monthly-raw'!J:J) -> 3.8105 | G5: =_xlfn.XLOOKUP(A:A,'Monthly-raw'!K:K,'Monthly-raw'!L:L) -> 16774.07
A6: 46171 | B6: =_xlfn.XLOOKUP(A:A,'Monthly-raw'!A:A,'Monthly-raw'!B:B) -> 7580.06 | C6: =_xlfn.XLOOKUP(A:A,'Monthly-raw'!C:C,'Monthly-raw'!D:D) -> 2357.7 | D6: =_xlfn.XLOOKUP(A:A,'Monthly-raw'!E:E,'Monthly-raw'!F:F) -> 242.04 | E6: =_xlfn.XLOOKUP(A:A,'Monthly-raw'!G:G,'Monthly-raw'!H:H) -> 15.32 | F6: =_xlfn.XLOOKUP(A:A,'Monthly-raw'!I:I,'Monthly-raw'!J:J) -> 3.67 | G6: =_xlfn.XLOOKUP(A:A,'Monthly-raw'!K:K,'Monthly-raw'!L:L) -> 16935.346
A7: 46142 | B7: =_xlfn.XLOOKUP(A:A,'Monthly-raw'!A:A,'Monthly-raw'!B:B) -> 7209.01 | C7: =_xlfn.XLOOKUP(A:A,'Monthly-raw'!C:C,'Monthly-raw'!D:D) -> 2350.38 | D7: =_xlfn.XLOOKUP(A:A,'Monthly-raw'!E:E,'Monthly-raw'!F:F) -> 241.29 | E7: =_xlfn.XLOOKUP(A:A,'Monthly-raw'!G:G,'Monthly-raw'!H:H) -> 16.89 | F7: =_xlfn.XLOOKUP(A:A,'Monthly-raw'!I:I,'Monthly-raw'!J:J) -> 3.6604 | G7: =_xlfn.XLOOKUP(A:A,'Monthly-raw'!K:K,'Monthly-raw'!L:L) -> 16088.562
A8: 46112 | B8: =_xlfn.XLOOKUP(A:A,'Monthly-raw'!A:A,'Monthly-raw'!B:B) -> 6528.52 | C8: =_xlfn.XLOOKUP(A:A,'Monthly-raw'!C:C,'Monthly-raw'!D:D) -> 2347.75 | D8: =_xlfn.XLOOKUP(A:A,'Monthly-raw'!E:E,'Monthly-raw'!F:F) -> 240.56 | E8: =_xlfn.XLOOKUP(A:A,'Monthly-raw'!G:G,'Monthly-raw'!H:H) -> 25.25 | F8: =_xlfn.XLOOKUP(A:A,'Monthly-raw'!I:I,'Monthly-raw'!J:J) -> 3.6718 | G8: =_xlfn.XLOOKUP(A:A,'Monthly-raw'!K:K,'Monthly-raw'!L:L) -> 14560.752
A9: 46080 | B9: =_xlfn.XLOOKUP(A:A,'Monthly-raw'!A:A,'Monthly-raw'!B:B) -> 6878.88 | C9: =_xlfn.XLOOKUP(A:A,'Monthly-raw'!C:C,'Monthly-raw'!D:D) -> 2389.86 | D9: =_xlfn.XLOOKUP(A:A,'Monthly-raw'!E:E,'Monthly-raw'!F:F) -> 239.84 | E9: =_xlfn.XLOOKUP(A:A,'Monthly-raw'!G:G,'Monthly-raw'!H:H) -> 19.86 | F9: =_xlfn.XLOOKUP(A:A,'Monthly-raw'!I:I,'Monthly-raw'!J:J) -> 3.6562 | G9: =_xlfn.XLOOKUP(A:A,'Monthly-raw'!K:K,'Monthly-raw'!L:L) -> 15323.803
A10: 46052 | B10: =_xlfn.XLOOKUP(A:A,'Monthly-raw'!A:A,'Monthly-raw'!B:B) -> 6939.03 | C10: =_xlfn.XLOOKUP(A:A,'Monthly-raw'!C:C,'Monthly-raw'!D:D) -> 2351.36 | D10: =_xlfn.XLOOKUP(A:A,'Monthly-raw'!E:E,'Monthly-raw'!F:F) -> 239.17 | E10: =_xlfn.XLOOKUP(A:A,'Monthly-raw'!G:G,'Monthly-raw'!H:H) -> 17.44 | F10: =_xlfn.XLOOKUP(A:A,'Monthly-raw'!I:I,'Monthly-raw'!J:J) -> 3.6537 | G10: =_xlfn.XLOOKUP(A:A,'Monthly-raw'!K:K,'Monthly-raw'!L:L) -> 15441.154
A11: 46022 | B11: =_xlfn.XLOOKUP(A:A,'Monthly-raw'!A:A,'Monthly-raw'!B:B) -> 6845.5 | C11: =_xlfn.XLOOKUP(A:A,'Monthly-raw'!C:C,'Monthly-raw'!D:D) -> 2348.85 | D11: =_xlfn.XLOOKUP(A:A,'Monthly-raw'!E:E,'Monthly-raw'!F:F) -> 238.46 | E11: =_xlfn.XLOOKUP(A:A,'Monthly-raw'!G:G,'Monthly-raw'!H:H) -> 14.95 | F11: =_xlfn.XLOOKUP(A:A,'Monthly-raw'!I:I,'Monthly-raw'!J:J) -> 3.6264 | G11: =_xlfn.XLOOKUP(A:A,'Monthly-raw'!K:K,'Monthly-raw'!L:L) -> 15220.455
A12: 45989 | B12: =_xlfn.XLOOKUP(A:A,'Monthly-raw'!A:A,'Monthly-raw'!B:B) -> 6849.09 | C12: =_xlfn.XLOOKUP(A:A,'Monthly-raw'!C:C,'Monthly-raw'!D:D) -> 2352.33 | D12: =_xlfn.XLOOKUP(A:A,'Monthly-raw'!E:E,'Monthly-raw'!F:F) -> 237.63 | E12: =_xlfn.XLOOKUP(A:A,'Monthly-raw'!G:G,'Monthly-raw'!H:H) -> 16.35 | F12: =_xlfn.XLOOKUP(A:A,'Monthly-raw'!I:I,'Monthly-raw'!J:J) -> 3.7956 | G12: =_xlfn.XLOOKUP(A:A,'Monthly-raw'!K:K,'Monthly-raw'!L:L) -> 15211.142
A13: 45961 | B13: =_xlfn.XLOOKUP(A:A,'Monthly-raw'!A:A,'Monthly-raw'!B:B) -> 6840.2 | C13: =_xlfn.XLOOKUP(A:A,'Monthly-raw'!C:C,'Monthly-raw'!D:D) -> 2337.8 | D13: =_xlfn.XLOOKUP(A:A,'Monthly-raw'!E:E,'Monthly-raw'!F:F) -> 236.93 | E13: =_xlfn.XLOOKUP(A:A,'Monthly-raw'!G:G,'Monthly-raw'!H:H) -> 17.44 | F13: =_xlfn.XLOOKUP(A:A,'Monthly-raw'!I:I,'Monthly-raw'!J:J) -> 3.8007 | G13: =_xlfn.XLOOKUP(A:A,'Monthly-raw'!K:K,'Monthly-raw'!L:L) -> 15173.95
... A362: 35338 | B362: =_xlfn.XLOOKUP(A:A,'Monthly-raw'!A:A,'Monthly-raw'!B:B) -> 687.31 | C362: =_xlfn.XLOOKUP(A:A,'Monthly-raw'!C:C,'Monthly-raw'!D:D) -> 684.83 | D362: =_xlfn.XLOOKUP(A:A,'Monthly-raw'!E:E,'Monthly-raw'!F:F) -> 123.07 | E362: =_xlfn.XLOOKUP(A:A,'Monthly-raw'!G:G,'Monthly-raw'!H:H) -> 16.95 | F362: =_xlfn.XLOOKUP(A:A,'Monthly-raw'!I:I,'Monthly-raw'!J:J) -> 5.032 | G362: =_xlfn.XLOOKUP(A:A,'Monthly-raw'!K:K,'Monthly-raw'!L:L) -> 898.966

Sheet US Banks-raw
A1: Weekly | J1: Monthly
A2: Date | B2: JPM US Equity (R1) | C2: MS US Equity (R1) | D2: GS US Equity (R2) | E2: C US Equity (R2) | F2: BAC US Equity (L1) | J2: Date | K2: JPM US Equity (R1) | L2: MS US Equity (R1) | M2: GS US Equity (R2) | N2: C US Equity (R2) | O2: BAC US Equity (L1)
A3: 46288 | B3: 337.8401 | C3: 198.53 | D3: 936.1997 | E3: 132.48 | F3: 55.785 | J3: 46288 | K3: 338.1201 | L3: 198.76 | M3: 937.15 | N3: 132.65 | O3: 55.845
A4: 46283 | B4: 349.67 | C4: 202.58 | D4: 942 | E4: 131.77 | F4: 57.73 | J4: 46265 | K4: 356.02 | L4: 213.32 | M4: 1025.9 | N4: 131.62 | O4: 61.94
A5: 46276 | B5: 356.23 | C5: 214.38 | D5: 1029.1801 | E5: 138.82 | F5: 62.69 | J5: 46234 | K5: 351.79 | L5: 210.42 | M5: 1018.38 | N5: 132.45 | O5: 61.95
A6: 46269 | B6: 358.64 | C6: 217.72 | D6: 1038.61 | E6: 137.72 | F6: 62.68 | J6: 46203 | K6: 327.33 | L6: 209.04 | M6: 1011.37 | N6: 139.96 | O6: 56.98
A7: 46262 | B7: 357.62 | C7: 214.77 | D7: 1033.99 | E7: 132.9 | F7: 62.32 | J7: 46171 | K7: 299.31 | L7: 208 | M7: 1025.5601 | N7: 125.9 | O7: 51.6
A8: 46255 | B8: 351.58 | C8: 214.2 | D8: 1039.28 | E8: 131.65 | F8: 61.69 | J8: 46142 | K8: 313.23 | L8: 190.59 | M8: 923.77 | N8: 127.98 | O8: 53.46
A9: 46248 | B9: 362.84 | C9: 217.36 | D9: 1039.42 | E9: 139.33 | F9: 64.49 | J9: 46112 | K9: 294.16 | L9: 164.57 | M9: 845.99 | N9: 113.41 | O9: 48.75
A10: 46241 | B10: 357.52 | C10: 216.33 | D10: 1039.61 | E10: 135 | F10: 63.17 | J10: 46080 | K10: 300.3 | L10: 166.51 | M10: 859.57 | N10: 110.19 | O10: 49.83
A11: 46234 | B11: 351.79 | C11: 210.42 | D11: 1018.38 | E11: 132.45 | F11: 61.95 | J11: 46052 | K11: 305.89 | L11: 182.8 | M11: 935.41 | N11: 115.71 | O11: 53.2
A12: 46227 | B12: 353.21 | C12: 214.48 | D12: 1061.23 | E12: 132.19 | F12: 62.05 | J12: 46022 | K12: 322.22 | L12: 177.53 | M12: 879 | N12: 116.69 | O12: 55
A13: 46220 | B13: 341.1 | C13: 215.5 | D13: 1065.22 | E13: 129.36 | F13: 61.27 | J13: 45989 | K13: 313.08 | L13: 169.66 | M13: 826.04 | N13: 103.6 | O13: 53.65
A14: 46213 | B14: 336.47 | C14: 222.28 | D14: 1055.1801 | E14: 140.79 | F14: 59.67 | J14: 45961 | K14: 311.12 | L14: 164 | M14: 789.37 | N14: 101.23 | O14: 53.45
... A331: 43994 | B331: 99.87 | C331: 46.28 | D331: 201.78 | E331: 52.25 | F331: 24.78 | J331: 36311 | K331: 48.25 | L331: 40.053 | M331: 67.9375 | N331: 308.101 | O331: 32.3438
A332: 43987 | B332: 111.23 | C332: 49.53 | D332: 217.92 | E332: 58.86 | F332: 28.11 | J332: 36280 | K332: 55 | L332: 41.1685 | N332: 348.2122 | O332: 35.7812
A333: 43980 | B333: 97.31 | C333: 44.2 | D333: 196.49 | E333: 47.91 | F333: 24.12 | J333: 36250 | K333: 54.25 | L333: 41.4798 | N333: 297.0559 | O333: 35.3125
A334: 43973 | B334: 89.47 | C334: 40.13 | D334: 179.93 | E334: 44.1 | F334: 22.66 | J334: 36217 | K334: 53.0833 | L334: 37.5627 | N334: 273.2216 | O334: 32.6562
A335: 43966 | B335: 85.9 | C335: 37.29 | D335: 171.87 | E335: 41.92 | F335: 21.44 | J335: 36189 | K335: 51.2917 | L335: 35.9544 | N335: 260.7232 | O335: 33.4375
A336: 43959 | B336: 92.7 | C336: 40.08 | D336: 185.39 | E336: 46.32 | F336: 23.57 | J336: 36160 | K336: 47.3333 | L336: 29.4691 | N336: 231.0757 | O336: 30.0625
A337: 43952 | B337: 93.25 | C337: 38.4 | D337: 177.1 | E337: 45.52 | F337: 23.08 | J337: 36129 | K337: 42.2917 | L337: 28.8984 | N337: 233.6917 | O337: 32.5938
A338: 43945 | B338: 90.71 | C338: 37.97 | D338: 177 | E338: 43.1 | F338: 22.18 | J338: 36098 | K338: 37.875 | L338: 26.9787 | N338: 218.5773 | O338: 28.75
A339: 43938 | B339: 95.18 | C339: 39.09 | D339: 183.49 | E339: 45.45 | F339: 23.28 | J339: 36068 | K339: 28.75 | L339: 17.8994 | N339: 174.3968 | O339: 26.75
A340: 43931 | B340: 102.76 | C340: 41.08 | D340: 184.26 | E340: 47.41 | F340: 24.86 | J340: 36038 | K340: 35 | L340: 24.0993 | N340: 206.3695 | O340: 28.75
A341: 43924 | B341: 84.05 | C341: 33.85 | D341: 146.93 | E341: 37.49 | F341: 20.03 | J341: 36007 | K341: 50.4167 | L341: 36.1359 | N341: 312.7516 | O341: 39.875
A342: 43917 | B342: 91.13 | C342: 34.01 | D342: 158.34 | E342: 43.8 | F342: 21.6 | J342: 35976 | K342: 50.3333 | L342: 37.9259 | N342: 281.9415 | O342: 38.3438
A343: 43910 | B343: 83.5 | C343: 29.67 | D343: 138.41 | E343: 38.06 | F343: 19.67 | J343: 35944 | K343: 45.3125 | L343: 32.4004 | N343: 284.8481 | O343: 37.75
... A363: 43770 | B363: 127.8 | C363: 47.33 | D363: 217.39 | E363: 73.84 | F363: 31.8 | J363: 35338 | K363: 26.7083 | L363: 11.4141 | N363: 114.2299 | O363: 21.7188
A364: 43763 | B364: 126.03 | C364: 46.37 | D364: 214.23 | E364: 73.17 | F364: 31.72
A365: 43756 | B365: 120.56 | C365: 43.66 | D365: 206.52 | E365: 69.74 | F365: 30.35
A366: 43749 | B366: 116.14 | C366: 41.93 | D366: 204.68 | E366: 70.1 | F366: 28.91
A367: 43742 | B367: 114.62 | C367: 40.78 | D367: 200.8 | E367: 68.18 | F367: 28.37
A368: 43735 | B368: 117.72 | C368: 42.84 | D368: 208.97 | E368: 69.46 | F368: 29.35
A369: 43728 | B369: 118.9 | C369: 43.67 | D369: 213.74 | E369: 69.35 | F369: 29.59
A370: 43721 | B370: 120.23 | C370: 45.16 | D370: 219.9 | E370: 70.39 | F370: 30.17
A371: 43714 | B371: 112.61 | C371: 42.18 | D371: 207.21 | E371: 65.97 | F371: 27.73
A372: 43707 | B372: 109.86 | C372: 41.49 | D372: 203.91 | E372: 64.35 | F372: 27.51
A373: 43700 | B373: 106.02 | C373: 39.33 | D373: 196.2 | E373: 61.95 | F373: 26.47
A374: 43693 | B374: 107.72 | C374: 39.94 | D374: 199.42 | E374: 63.48 | F374: 27.03
A375: 43686 | B375: 109.74 | C375: 41.5 | D375: 206.9 | E375: 66.05 | F375: 28.33
...
